<robot
  name="sirdigsalot">
  <link name="base_footprint"/>
  <joint name="base_joint" type="fixed">
    <parent link = "base_footprint"/>
    <child link="base_link"/>
    <origin xyz="0.0 0.0 0.5" rpy="0 0 0 "/>
  </joint>
  <link
    name="base_link">
    <visual>
      <origin
        xyz="0 0 0"
        rpy="0 0 0" />
      <geometry>
        <mesh
          filename="package://lk_rmc_description/meshes/base_link.STL" />
      </geometry>
      <material
        name="">
        <color
          rgba="0.79216 0.81961 0.93333 1" />
      </material>
    </visual>
    <collision>
      <origin
        xyz="0 0 0"
        rpy="0 0 0" />
      <geometry>
        <mesh
          filename="package://lk_rmc_description/meshes/base_link.STL" />
      </geometry>
    </collision>
    <inertial>
      <origin xyz="0 0 -.25" rpy="0 0 0"/>
      <mass value="12"/>
      <inertia
        ixx="1.0" ixy="0.0" ixz="0.0"
        iyy="1.0" iyz="0.0"
        izz="1.0"/>
    </inertial>
  </link>
  <link
    name="frontLeftWheel">
    <visual>
      <origin
        xyz="0 0 0"
        rpy="0 0 0" />
      <geometry>
          <cylinder length=".1016" radius=".1524"/>
      </geometry>
      <material
        name="">
        <color
          rgba="0.79216 0.81961 0.93333 1" />
      </material>
    </visual>
    <collision>
      <origin
        xyz="0 0 0"
        rpy="0 0 0" />
      <geometry>
        <cylinder length=".1016" radius=".1524"/>
      </geometry>
    </collision>
    <inertial>
      <origin xyz="0 0 0" rpy="0 0 0"/>
      <mass value="5"/>
      <inertia
        ixx="1.0" ixy="0.0" ixz="0.0"
        iyy="1.0" iyz="0.0"
        izz="1.0"/>
    </inertial>
  </link>
  <joint
    name="frontLeftWheelRotate"
    type="continuous">
    <origin
      xyz="0.30464 0.23782 -0.28624"
      rpy="1.5708 0.0022295 -1.3651E-19" />
    <parent
      link="base_link" />
    <child
      link="frontLeftWheel" />
    <axis
      xyz="0 0 1" />
  </joint>
  <link
    name="backLeftWheel">
    <visual>
      <origin
        xyz="0 0 0"
        rpy="0 0 0" />
      <geometry>
        <cylinder length=".1016" radius=".1524"/>
      </geometry>
      <material
        name="">
        <color
          rgba="0.79216 0.81961 0.93333 1" />
      </material>
    </visual>
    <collision>
      <origin
        xyz="0 0 0"
        rpy="0 0 0" />
      <geometry>
        <cylinder length=".1016" radius=".1524"/>
      </geometry>
    </collision>
    <inertial>
      <origin xyz="0 0 0" rpy="0 0 0"/>
      <mass value="5"/>
      <inertia
        ixx="1.0" ixy="0.0" ixz="0.0"
        iyy="1.0" iyz="0.0"
        izz="1.0"/>
    </inertial>
  </link>
  <joint
    name="backLeftWheelRotate"
    type="continuous">
    <origin
      xyz="-0.30496 0.23782 -0.28624"
      rpy="1.5708 -0.71925 -3.6358E-15" />
    <parent
      link="base_link" />
    <child
      link="backLeftWheel" />
    <axis
      xyz="0 0 1" />
  </joint>
  <link
    name="frontRightWheel">
    <visual>
      <origin
        xyz="0 0 0"
        rpy="0 0 0" />
      <geometry>
        <cylinder length=".1016" radius=".1524"/>
      </geometry>
      <material
        name="">
        <color
          rgba="0.79216 0.81961 0.93333 1" />
      </material>
    </visual>
    <collision>
      <origin
        xyz="0 0 0"
        rpy="0 0 0" />
      <geometry>
        <cylinder length=".1016" radius=".1524"/>
      </geometry>
    </collision>
    <inertial>
      <origin xyz="0 0 0" rpy="0 0 0"/>
      <mass value="5"/>
      <inertia
        ixx="1.0" ixy="0.0" ixz="0.0"
        iyy="1.0" iyz="0.0"
        izz="1.0"/>
    </inertial>
  </link>
  <joint
    name="frontRightWheelRotate"
    type="continuous">
    <origin
      xyz="0.30464 -0.2416 -0.28624"
      rpy="1.5708 -0.055957 3.4299E-18" />
    <parent
      link="base_link" />
    <child
      link="frontRightWheel" />
    <axis
      xyz="0 0 1" />
  </joint>
  <joint
    name="backRightWheelRotate"
    type="continuous">
    <origin
      xyz="-0.30496 -0.2416 -0.28624"
      rpy="1.5708 0 0" />
    <parent
      link="base_link" />
    <child
      link="backRightWheel" />
    <axis
      xyz="0 0 1" />
  </joint>
  <link
    name="backRightWheel">
    <visual>
      <origin
        xyz="0 0 0"
        rpy="0 0 0" />
      <geometry>
        <cylinder length=".1016" radius=".1524"/>
      </geometry>
      <material
        name="">
        <color
          rgba="0.792156862745098 0.819607843137255 0.933333333333333 1" />
      </material>
    </visual>
    <collision>
      <origin
        xyz="0 0 0"
        rpy="0 0 0" />
      <geometry>
        <cylinder length=".1016" radius=".1524"/>
      </geometry>
    </collision>
    <inertial>
      <origin xyz="0 0 0" rpy="0 0 0"/>
      <mass value="5"/>
      <inertia
        ixx="1.0" ixy="0.0" ixz="0.0"
        iyy="1.0" iyz="0.0"
        izz="1.0"/>
    </inertial>
  </link>

  <gazebo>
    <plugin name="gazebo_ros_control" filename="libgazebo_ros_control.so">
      <robotNamespace></robotNamespace>
      <!--robotParam>/robot_description</robotParam-->
      <robotSimType>gazebo_ros_control/DefaultRobotHWSim</robotSimType>
    </plugin>
  </gazebo>

  <transmission name="backLeftWheelTrans" type="SimpleTransmission">
    <type>transmission_interface/SimpleTransmission</type>
    <actuator name="backLeftWheelMotor">
      <mechanicalReduction>1</mechanicalReduction>
      <hardwareInterface>VelocityJointInterface</hardwareInterface>
    </actuator>
    <joint name="backLeftWheelRotate">
      <hardwareInterface>hardware_interface/VelocityJointInterface</hardwareInterface>
    </joint>
  </transmission>
  
  <transmission name="frontLeftWheelTrans" type="SimpleTransmission">
    <type>transmission_interface/SimpleTransmission</type>
    <actuator name="frontLeftWheelMotor">
      <mechanicalReduction>1</mechanicalReduction>
      <hardwareInterface>VelocityJointInterface</hardwareInterface>
    </actuator>
    <joint name="frontLeftWheelRotate">
      <hardwareInterface>hardware_interface/VelocityJointInterface</hardwareInterface>
    </joint>
  </transmission>

  <transmission name="backRightWheelTrans" type="SimpleTransmission">
    <type>transmission_interface/SimpleTransmission</type>
    <actuator name="backRightWheelMotor">
      <mechanicalReduction>1</mechanicalReduction>
      <hardwareInterface>VelocityJointInterface</hardwareInterface>
    </actuator>
    <joint name="backRightWheelRotate">
      <hardwareInterface>hardware_interface/VelocityJointInterface</hardwareInterface>
    </joint>
  </transmission>

  <transmission name="frontRightWheelTrans" type="SimpleTransmission">
    <type>transmission_interface/SimpleTransmission</type>
    <actuator name="frontRightWheelMotor">
      <mechanicalReduction>1</mechanicalReduction>
      <hardwareInterface>VelocityJointInterface</hardwareInterface>
    </actuator>
    <joint name="frontRightWheelRotate">
      <hardwareInterface>hardware_interface/VelocityJointInterface</hardwareInterface>
    </joint>
  </transmission>

</robot>