<robot name="sirdigsalot">
  <!--Base Settings-->
  <link name="base_footprint"/>

  <joint name="base_joint" type="fixed">
    <parent link = "base_footprint"/>
    <child link="base_link"/>
    <origin xyz="0.0 0.0 0.5" rpy="0 0 0 "/>
  </joint>

  <link name="base_link">
    <visual>
      <origin
        xyz="0 0 0"
        rpy="0 0 0" />
      <geometry>
        <mesh
          filename="package://lk_rmc_description/meshes/base_link.STL" />
      </geometry>
      <material
        name="">
        <color
          rgba="0.79216 0.81961 0.93333 1" />
      </material>
    </visual>
    <collision>
      <origin
        xyz="0 0 0"
        rpy="0 0 0" />
      <geometry>
        <mesh
          filename="package://lk_rmc_description/meshes/base_link.STL" />
      </geometry>
    </collision>
    <inertial>
      <origin xyz="0 0 -.25" rpy="0 0 0"/>
      <mass value="12"/>
      <inertia
        ixx="1.0" ixy="0.0" ixz="0.0"
        iyy="1.0" iyz="0.0"
        izz="1.0"/>
    </inertial>
  </link>

  <!--Front Left Wheel Settings-->
  <link name="backLeftWheel">
    <visual>
      <origin
        xyz="0 0 0"
        rpy="0 0 0" />
      <geometry>
          <cylinder length=".1016" radius=".1524"/>
      </geometry>
      <material name="">
        <color rgba="0.79216 0.81961 0.93333 1" />
      </material>
    </visual>
    <collision>
      <origin
        xyz="0 0 0"
        rpy="0 0 0" />
      <geometry>
        <cylinder length=".1016" radius=".1524"/>
      </geometry>
    </collision>
    <inertial>
      <origin xyz="0 0 0" rpy="0 0 0"/>
      <!--Old mass=5******************************************************-->
      <mass value="2.37"/>
      <inertia
        ixx="1.0" ixy="0.0" ixz="0.0"
        iyy="1.0" iyz="0.0"
        izz="1.0"/>
    </inertial>
  </link>

  <joint
    name="backLeftWheelRotate"
    type="continuous">
    <!--
    <origin
      xyz="0.30464 0.23782 -0.28624"
      rpy="1.5708 0.0022295 -1.3651E-19" />
    -->
    <origin
      xyz="0.30464 0.2885 -0.28624"
      rpy="1.5708 0.0022295 -1.3651E-19" />
    <parent link="base_link" />
    <child link="backLeftWheel" />
    <axis xyz="0 0 1" />
  </joint>

  <transmission name="backLeftWheelTrans" type="SimpleTransmission">
    <type>transmission_interface/SimpleTransmission</type>
    <actuator name="backLeftWheelMotor">
      <mechanicalReduction>1</mechanicalReduction>
      <hardwareInterface>VelocityJointInterface</hardwareInterface>
    </actuator>
    <joint name="backLeftWheelRotate">
      <hardwareInterface>hardware_interface/VelocityJointInterface</hardwareInterface>
    </joint>
  </transmission>

  <!--Back Left Wheel Settings-->
  <link name="frontLeftWheel">
    <visual>
      <origin
        xyz="0 0 0"
        rpy="0 0 0" />
      <geometry>
        <cylinder length=".1016" radius=".1524"/>
      </geometry>
      <material
        name="">
        <color
          rgba="0.79216 0.81961 0.93333 1" />
      </material>
    </visual>
    <collision>
      <origin
        xyz="0 0 0"
        rpy="0 0 0" />
      <geometry>
        <cylinder length=".1016" radius=".1524"/>
      </geometry>
    </collision>
    <inertial>
      <origin xyz="0 0 0" rpy="0 0 0"/>
      <mass value="2.37"/>
      <inertia
        ixx="1.0" ixy="0.0" ixz="0.0"
        iyy="1.0" iyz="0.0"
        izz="1.0"/>
    </inertial>
  </link>

  <joint
    name="frontLeftWheelRotate"
    type="continuous">
    <!--
    <origin
      xyz="-0.30496 0.23782 -0.28624"
      rpy="1.5708 -0.71925 -3.6358E-15" />
    -->
    <origin
      xyz="-0.30496 0.2885 -0.28624"
      rpy="1.5708 -0.71925 -3.6358E-15" />
    <parent link="base_link" />
    <child link="frontLeftWheel" />
    <axis xyz="0 0 1" />
  </joint>

  <transmission name="frontLeftWheelTrans" type="SimpleTransmission">
    <type>transmission_interface/SimpleTransmission</type>
    <actuator name="frontLeftWheelMotor">
      <mechanicalReduction>1</mechanicalReduction>
      <hardwareInterface>VelocityJointInterface</hardwareInterface>
    </actuator>
    <joint name="frontLeftWheelRotate">
      <hardwareInterface>hardware_interface/VelocityJointInterface</hardwareInterface>
    </joint>
  </transmission>

  <!--Front Right Wheel Settings-->
  <link name="backRightWheel">
    <visual>
      <origin
        xyz="0 0 0"
        rpy="0 0 0" />
      <geometry>
        <cylinder length=".1016" radius=".1524"/>
      </geometry>
      <material
        name="">
        <color
          rgba="0.79216 0.81961 0.93333 1" />
      </material>
    </visual>
    <collision>
      <origin
        xyz="0 0 0"
        rpy="0 0 0" />
      <geometry>
        <cylinder length=".1016" radius=".1524"/>
      </geometry>
    </collision>
    <inertial>
      <origin xyz="0 0 0" rpy="0 0 0"/>
      <mass value="2.37"/>
      <inertia
        ixx="1.0" ixy="0.0" ixz="0.0"
        iyy="1.0" iyz="0.0"
        izz="1.0"/>
    </inertial>
  </link>
  <joint
    name="backRightWheelRotate"
    type="continuous">
    <!--
    <origin
      xyz="0.30464 -0.2416 -0.28624"
      rpy="1.5708 -0.055957 3.4299E-18" />
    -->
    <!--r changes the yellow arrow side to point to the robot-->
    <origin
      xyz="0.30464 -0.2924 -0.28624"
      rpy="-1.5708 -0.055957 3.4299E-18" />
    <parent link="base_link" />
    <child link="backRightWheel" />
    <axis xyz="0 0 1" />
  </joint>
  <transmission name="backRightWheelTrans" type="SimpleTransmission">
    <type>transmission_interface/SimpleTransmission</type>
    <actuator name="backRightWheelMotor">
      <mechanicalReduction>1</mechanicalReduction>
      <hardwareInterface>VelocityJointInterface</hardwareInterface>
    </actuator>
    <joint name="backRightWheelRotate">
      <hardwareInterface>hardware_interface/VelocityJointInterface</hardwareInterface>
    </joint>
  </transmission>

  <!--Back Right Wheel Settings-->
  <link name="frontRightWheel">
    <visual>
      <origin
        xyz="0 0 0"
        rpy="0 0 0" />
      <geometry>
        <cylinder length=".1016" radius=".1524"/>
      </geometry>
      <material
        name="">
        <color
          rgba="0.792156862745098 0.819607843137255 0.933333333333333 1" />
      </material>
    </visual>
    <collision>
      <origin
        xyz="0 0 0"
        rpy="0 0 0" />
      <geometry>
        <cylinder length=".1016" radius=".1524"/>
      </geometry>
    </collision>
    <inertial>
      <origin xyz="0 0 0" rpy="0 0 0"/>
      <mass value="2.37"/>
      <inertia
        ixx="1.0" ixy="0.0" ixz="0.0"
        iyy="1.0" iyz="0.0"
        izz="1.0"/>
    </inertial>
  </link>
  <joint
    name="frontRightWheelRotate"
    type="continuous">
    <!--
    <origin
      xyz="-0.30496 -0.2416 -0.28624"
      rpy="1.5708 0 0" />
    -->
    <origin
      xyz="-0.30496 -0.2924 -0.28624"
      rpy="-1.5708 0 0" />
    <parent link="base_link" />
    <child link="frontRightWheel" />
    <axis xyz="0 0 1" />
  </joint>
  <transmission name="frontRightWheelTrans" type="SimpleTransmission">
    <type>transmission_interface/SimpleTransmission</type>
    <actuator name="frontRightWheelMotor">
      <mechanicalReduction>1</mechanicalReduction>
      <hardwareInterface>VelocityJointInterface</hardwareInterface>
    </actuator>
    <joint name="frontRightWheelRotate">
      <hardwareInterface>hardware_interface/VelocityJointInterface</hardwareInterface>
    </joint>
  </transmission>

  <gazebo>
    <plugin name="gazebo_ros_control" filename="libgazebo_ros_control.so">
      <robotNamespace></robotNamespace>
      <!--robotParam>/robot_description</robotParam-->
      <robotSimType>gazebo_ros_control/DefaultRobotHWSim</robotSimType>
    </plugin>
  </gazebo>

  <!--Laser Settings-->
  <link name="laser_link"/>
  <joint name="laser_link" type="fixed">
    <parent link = "base_link"/>
    <child link="laser_link"/>
    <origin xyz="0.43 0.0 -0.2" rpy="0 0 0 "/>
  </joint>
  <gazebo reference="laser_link">
    <sensor type="ray" name="head_hokuyo_sensor">
      <pose>0 0 0 0 0 0</pose>
      <visualize>true</visualize>
      <update_rate>40</update_rate>
      <ray>
        <scan>
          <horizontal>
            <samples>720</samples>
            <resolution>1</resolution>
            <min_angle>-1.3</min_angle>
            <max_angle>1.3</max_angle>
          </horizontal>
        </scan>
        <range>
          <min>0.10</min>
          <max>10.0</max>
          <resolution>0.01</resolution>
        </range>
        <noise>
          <type>gaussian</type>
          <!-- Noise parameters based on published spec for Hokuyo laser
               achieving "+-30mm" accuracy at range < 10m.  A mean of 0.0m and
               stddev of 0.01m will put 99.7% of samples within 0.03m of the true
               reading. -->
          <mean>0.0</mean>
          <stddev>0.01</stddev>
        </noise>
      </ray>
      <plugin name="gazebo_ros_head_hokuyo_controller" filename="libgazebo_ros_laser.so">
        <topicName>/scan</topicName>
        <frameName>laser_link</frameName>
      </plugin>
    </sensor>
  </gazebo>
</robot>
